output.csv
ASK,7,16062
ASK,12,16037
BID,98,16037
BID,60,16009
ASK,24,16045
ASK,14,16071
ASK,44,16091
ASK,26,16037
BID,10,16045
BID,9,16038
ASK,46,16081
ASK,94,16038
BID,73,16020
ASK,3,16037
BID,80,16038
BID,3,16013
ASK,49,16099
ASK,9,16071
ASK,60,16094
BID,92,16038
ASK,49,16096
ASK,16,16072
ASK,69,16078
BID,64,16045
ASK,42,16055
BID,33,16050
ASK,37,16069
ASK,16,16050
BID,13,16055
BID,77,16055
BID,86,16020
BID,60,16000
ASK,10,16069
BID,71,16014
BID,52,16015
ASK,79,16080
ASK,84,16055
ASK,90,16071
ASK,9,16050
BID,17,16055
BID,54,16045
ASK,47,16050
ASK,33,16045
ASK,71,16045
ASK,87,16038
ASK,31,16037
BID,33,16050
BID,42,16050
BID,91,16055
BID,41,16001
ASK,55,16055
BID,81,16062
ASK,31,16078
ASK,44,16062
BID,56,16069
ASK,85,16071
ASK,14,16088
BID,5,16024
BID,68,16071
ASK,43,16069
BID,98,16036
ASK,1,16093
BID,62,16069
BID,53,16060
ASK,97,16070
ASK,80,16069
BID,8,16056
ASK,61,16062
ASK,70,16068
ASK,37,16060
ASK,89,16091
BID,27,16051
BID,73,16020
ASK,47,16060
ASK,38,16056
ASK,86,16055
BID,47,16037
BID,89,16055
BID,79,16056
BID,52,16060
BID,15,16062
BID,59,16029
BID,67,16062
ASK,35,16062
ASK,40,16062
ASK,53,16060
BID,76,16060
BID,28,16034
ASK,51,16060
BID,24,16060
ASK,73,16082
BID,62,16062
ASK,35,16062
ASK,11,16062
BID,91,16062
BID,94,16042
ASK,33,16062
BID,45,16068
ASK,30,16062
BID,11,16035
ASK,74,16064
BID,78,16064
ASK,4,16064
BID,9,16057
BID,51,16033
BID,24,16031
BID,32,16054
BID,48,16018
ASK,71,16062
BID,52,16027
ASK,13,16098
ASK,0,16060
ASK,89,16080
ASK,66,16077
ASK,99,16095
BID,99,16000
BID,2,16048
BID,29,16062
BID,42,16062
BID,63,16007
ASK,98,16062
ASK,75,16060
ASK,18,16070
BID,70,16021
ASK,90,16057
BID,6,16011
BID,52,16057
BID,36,16057
BID,73,16060
BID,88,16062
ASK,34,16063
ASK,88,16062
ASK,80,16060
BID,74,16035
ASK,95,16057
BID,86,16051
BID,89,16057
ASK,84,16057
BID,38,16042
BID,97,16012
BID,40,16057
BID,76,16057
ASK,17,16061
BID,62,16000
ASK,94,16057
BID,89,16031
ASK,11,16086
BID,17,16057
BID,99,16057
BID,11,16060
ASK,29,16057
BID,32,16029
ASK,54,16057
ASK,14,16056
ASK,10,16069
ASK,22,16060
ASK,16,16056
ASK,63,16056
ASK,61,16055
ASK,89,16059
ASK,1,16054
BID,19,16055
ASK,73,16054
BID,89,16054
BID,27,16012
ASK,4,16054
ASK,34,16092
BID,34,16006
BID,22,16020
ASK,5,16072
BID,14,16046
BID,41,16055
BID,2,16056
ASK,62,16055
ASK,79,16054
ASK,18,16051
BID,64,16054
ASK,33,16054
BID,94,16021
BID,0,16002
ASK,48,16051
BID,64,16054
ASK,94,16054
BID,98,16054
BID,11,16000
BID,57,16055
BID,8,16029
BID,43,16056
BID,49,16035
ASK,33,16056
ASK,59,16092
ASK,39,16072
ASK,13,16097
BID,92,16056
ASK,41,16056
ASK,30,16056
BID,13,16056
BID,56,16011
BID,12,16030
BID,65,16057
ASK,91,16073
BID,96,16059
BID,3,16015
ASK,87,16059
BID,17,16059
BID,46,16029
ASK,28,16071
BID,32,16059
BID,89,16059
BID,10,16009
BID,50,16051
BID,94,16060
ASK,56,16081
ASK,22,16060
BID,13,16053
ASK,58,16059
BID,74,16060
ASK,24,16075
ASK,42,16060
ASK,5,16076
BID,16,16061
BID,41,16009
BID,38,16061
ASK,89,16061
BID,26,16061
BID,8,16029
ASK,19,16071
ASK,50,16082
BID,32,16061
ASK,31,16061
BID,50,16022
BID,87,16061
BID,98,16062
ASK,2,16062
BID,64,16027
ASK,39,16062
BID,40,16039
ASK,70,16066
ASK,15,16061
ASK,85,16061
BID,81,16061
BID,41,16047
ASK,38,16061
BID,76,16018
BID,65,16062
BID,13,16063
ASK,49,16083
ASK,34,16098
ASK,34,16062
ASK,82,16062
ASK,83,16061
BID,0,16061
ASK,63,16095
ASK,17,16060
BID,13,16049
BID,43,16019
ASK,11,16060
ASK,63,16057
ASK,40,16056
BID,51,16051
ASK,17,16060
ASK,20,16055
ASK,47,16058
ASK,97,16054
ASK,93,16062
ASK,85,16082
BID,95,16009
ASK,87,16053
ASK,33,16079
BID,56,16036
ASK,65,16072
BID,59,16031
ASK,67,16057
BID,92,16053
BID,54,16054
BID,33,16055
ASK,41,16055
BID,96,16055
BID,46,16056
BID,12,16057
BID,63,16057
BID,73,16037
BID,83,16006
BID,67,16010
BID,12,16032
ASK,92,16092
ASK,5,16056
BID,13,16043
BID,64,16057
BID,29,16058
ASK,42,16084
ASK,78,16095
ASK,47,16057
ASK,23,16094
BID,28,16023
ASK,34,16056
ASK,84,16055
ASK,42,16087
ASK,79,16055
BID,53,16010
ASK,66,16096
ASK,36,16054
BID,74,16054
ASK,28,16054
BID,90,16055
BID,51,16045
BID,10,16033
ASK,35,16055
BID,97,16055
BID,55,16051
BID,5,16044
ASK,30,16083
ASK,65,16055
ASK,7,16055
ASK,77,16054
ASK,35,16053
ASK,36,16051
ASK,59,16051
ASK,53,16097
BID,44,16051
ASK,18,16051
ASK,34,16051
ASK,99,16068
ASK,74,16051
ASK,32,16051
BID,5,16018
BID,68,16051
ASK,53,16051
ASK,49,16085
ASK,17,16052
BID,68,16049
ASK,37,16097
ASK,99,16058
BID,29,16052
BID,77,16053
ASK,75,16053
BID,57,16016
BID,4,16012
ASK,90,16052
BID,54,16010
BID,85,16052
BID,23,16053
ASK,70,16091
ASK,94,16086
BID,1,16053
BID,34,16003
BID,99,16054
ASK,79,16071
ASK,54,16054
ASK,77,16053
ASK,70,16052
ASK,82,16051
BID,16,16051
BID,70,16051
ASK,25,16051
ASK,25,16050
BID,54,16006
ASK,58,16050
BID,16,16050
BID,40,16021
ASK,18,16049
ASK,82,16049
ASK,86,16048
BID,25,16017
ASK,50,16093
ASK,95,16047
ASK,66,16063
ASK,40,16046
ASK,57,16045
BID,78,16002
ASK,22,16044
ASK,48,16057
ASK,61,16095
ASK,83,16043
ASK,8,16057
BID,51,16023
BID,42,16042
ASK,88,16042
BID,88,16001
ASK,52,16070
BID,56,16043
ASK,3,16043
ASK,11,16042
ASK,17,16099
BID,86,16008
BID,24,16043
ASK,65,16078
ASK,31,16093
BID,22,16044
ASK,61,16044
BID,59,16044
BID,78,16016
BID,82,16045
ASK,25,16078
ASK,40,16074
ASK,31,16087
BID,97,16017
BID,75,16013
ASK,63,16045
ASK,87,16055
ASK,52,16045
ASK,25,16087
BID,14,16045
ASK,7,16044
ASK,48,16071
ASK,95,16065
BID,63,16044
ASK,53,16078
BID,48,16031
ASK,99,16044
ASK,36,16055
ASK,14,16097
BID,92,16044
BID,88,16045
BID,69,16039
ASK,96,16045
BID,76,16045
ASK,6,16093
ASK,72,16066
ASK,82,16075
ASK,48,16094
BID,74,16046
BID,54,16047
BID,92,16048
ASK,17,16048
BID,49,16048
ASK,88,16054
ASK,11,16048
ASK,21,16048
ASK,60,16069
ASK,65,16048
ASK,53,16046
ASK,93,16093
BID,20,16046
BID,14,16048
ASK,83,16063
BID,59,16048
BID,0,16049
ASK,29,16077
ASK,61,16048
BID,84,16048
BID,33,16049
BID,75,16031
ASK,93,16049
ASK,35,16052
BID,12,16049
ASK,84,16048
BID,23,16012
BID,47,16048
ASK,11,16048
BID,41,16048
BID,80,16049
BID,92,16012
BID,93,16050
BID,36,16051
BID,20,16052
ASK,12,16051
ASK,76,16071
ASK,37,16078
ASK,22,16051
ASK,70,16070
ASK,47,16050
ASK,26,16070
BID,52,16051
BID,84,16036
BID,61,16004
BID,82,16052
ASK,82,16063
BID,58,16053
ASK,41,16052
BID,55,16047
ASK,37,16099
BID,68,16004
ASK,7,16055
BID,33,16041
BID,44,16010
BID,17,16032
BID,4,16052
BID,71,16052
BID,50,16053
ASK,70,16053
ASK,38,16056
BID,3,16004
ASK,85,16054
BID,65,16033
ASK,55,16061
BID,34,16053
BID,16,16044
BID,66,16001
BID,72,16023
ASK,63,16053
ASK,20,16089
BID,72,16050
BID,63,16053
ASK,70,16072
BID,82,16046
BID,54,16012
BID,66,16054
ASK,30,16098
ASK,82,16053
BID,93,16000
BID,27,16018
ASK,27,16052
BID,91,16040
ASK,78,16052
BID,13,16046
BID,2,16052
BID,0,16015
ASK,89,16051
ASK,23,16080
ASK,78,16083
ASK,53,16050
ASK,21,16061
ASK,32,16081
ASK,76,16093
BID,19,16051
ASK,48,16050
BID,16,16050
BID,40,16007
ASK,90,16050
BID,83,16019
BID,31,16027
ASK,6,16099
BID,41,16017
ASK,18,16087
ASK,48,16054
ASK,40,16049
BID,86,16049
BID,38,16004
ASK,36,16053
ASK,78,16051
BID,19,16050
ASK,60,16069
BID,61,16025
ASK,29,16085
BID,14,16050
ASK,58,16080
BID,87,16050
BID,62,16051
ASK,0,16050
ASK,5,16050
ASK,66,16055
BID,10,16051
BID,93,16051
BID,57,16038
BID,94,16052
BID,54,16053
ASK,11,16079
ASK,37,16054
BID,47,16053
BID,57,16023
ASK,16,16090
BID,28,16053
ASK,55,16099
ASK,30,16053
ASK,52,16099
BID,50,16009
BID,91,16044
ASK,81,16092
BID,88,16053
BID,0,16017
BID,59,16024
BID,82,16030
ASK,55,16053
ASK,50,16053
BID,40,16001
ASK,16,16064
BID,58,16052
BID,10,16053
ASK,28,16052
BID,21,16053
ASK,73,16052
BID,11,16052
BID,44,16022
ASK,67,16097
BID,20,16000
BID,69,16052
BID,86,16045
ASK,31,16087
ASK,32,16078
BID,44,16033
BID,28,16053
BID,61,16044
ASK,81,16085
ASK,51,16053
ASK,5,16052
BID,27,16045
ASK,82,16052
BID,6,16020
BID,63,16052
BID,96,16001
ASK,64,16064
BID,5,16030
BID,32,16053
BID,82,16045
ASK,44,16053
BID,68,16053
BID,42,16054
ASK,93,16074
ASK,99,16053
BID,32,16039
ASK,62,16096
ASK,19,16060
BID,99,16053
ASK,36,16053
ASK,73,16052
ASK,12,16051
BID,4,16052
ASK,61,16051
BID,89,16051
ASK,38,16051
BID,4,16051
BID,64,16052
BID,75,16053
BID,17,16054
ASK,14,16053
BID,11,16028
BID,26,16050
BID,69,16047
ASK,79,16053
